{
  "comments": [
    {
      "unresolved": true,
      "key": {
        "uuid": "ed722685_4e58c31e",
        "filename": "dump/dump_manager.cpp",
        "patchSetId": 6
      },
      "lineNbr": 307,
      "author": {
        "id": 1000089
      },
      "writtenOn": "2023-01-04T12:04:39Z",
      "side": 1,
      "message": "why do we need to catch this InternalFailure exception? setProperty does not throw this exception?",
      "revId": "fa923348e9d94bcc56dd5c67839f1c810cbf6131",
      "serverId": "adbd0a64-1f21-4d83-b585-671fe73cb6e4"
    }
  ]
}